<?xml version="1.0" encoding="utf-8"?>
<!-- This URDF was automatically created by SolidWorks to URDF Exporter! Originally created by Stephen Brawner (brawner@gmail.com) 
     Commit Version: 1.6.0-4-g7f85cfe  Build Version: 1.6.7995.38578
     For more information, please see http://wiki.ros.org/sw_urdf_exporter -->
<robot
  name="抓取机器人export_urdf.SLDASM">
  <link
    name="base_link">
    <inertial>
      <origin
        xyz="0.00048381 0.0032191 0.050559"
        rpy="0 0 0" />
      <mass
        value="3" />
      <inertia
        ixx="0.00045119"
        ixy="1.4679E-06"
        ixz="-1.2424E-07"
        iyy="0.00050737"
        iyz="-7.1838E-07"
        izz="0.00089983" />
    </inertial>
    <visual>
      <origin
        xyz="0 0 0"
        rpy="0 0 0" />
      <geometry>
        <mesh
          filename="../meshes/body_link.STL" />
      </geometry>
      <material
        name="">
        <color
          rgba="1 1 1 1" />
      </material>
    </visual>
    <collision>
      <origin
        xyz="0 0 0"
        rpy="0 0 0" />
      <geometry>
        <mesh
          filename="../meshes/body_link.STL" />
      </geometry>
    </collision>
  </link>
  <link
    name="lf_thigh_Link">
    <inertial>
      <origin
        xyz="0.019013 0.00032996 0.00086404"
        rpy="0 0 0" />
      <mass
        value="0.071" />
      <inertia
        ixx="2.5711E-06"
        ixy="1.9851E-08"
        ixz="-8.344E-08"
        iyy="2.9345E-06"
        iyz="-5.4072E-09"
        izz="4.3664E-06" />
    </inertial>
    <visual>
      <origin
        xyz="0 0 0"
        rpy="0 0 0" />
      <geometry>
        <mesh
          filename="../meshes/thigh_link.STL" />
      </geometry>
      <material
        name="">
        <color
          rgba="1 1 1 1" />
      </material>
    </visual>
    <collision>
      <origin
        xyz="0 0 0"
        rpy="0 0 0" />
      <geometry>
        <mesh
          filename="../meshes/thigh_link.STL" />
      </geometry>
    </collision>
  </link>
  <joint
    name="lf_thigh_joint"
    type="revolute">
    <origin
      xyz="-0.0425 0.073612 0.025246"
      rpy="0 0 2.0944" />
    <parent
      link="base_link" />
    <child
      link="lf_thigh_Link" />
    <axis
      xyz="0 0 -1" />
    <limit
      lower="-1.571"
      upper="0.698"
      effort="1.2"
      velocity="4" />
  </joint>
  <link
    name="lf_knee_Link">
    <inertial>
      <origin
        xyz="0.024 0.00029496 0.00079694"
        rpy="0 0 0" />
      <mass
        value="0.079" />
      <inertia
        ixx="3.459E-06"
        ixy="1.9852E-08"
        ixz="-8.3439E-08"
        iyy="6.155E-06"
        iyz="-5.4073E-09"
        izz="4.8098E-06" />
    </inertial>
    <visual>
      <origin
        xyz="0 0 0"
        rpy="0 0 0" />
      <geometry>
        <mesh
          filename="../meshes/knee_link.STL" />
      </geometry>
      <material
        name="">
        <color
          rgba="1 1 1 1" />
      </material>
    </visual>
    <collision>
      <origin
        xyz="0 0 0"
        rpy="0 0 0" />
      <geometry>
        <mesh
          filename="../meshes/knee_link.STL" />
      </geometry>
    </collision>
  </link>
  <joint
    name="lf_knee_joint"
    type="revolute">
    <origin
      xyz="0.05236 0 0"
      rpy="1.5708 0 0" />
    <parent
      link="lf_thigh_Link" />
    <child
      link="lf_knee_Link" />
    <axis
      xyz="0 0 -1" />
    <limit
      lower="-2.094"
      upper="2.094"
      effort="1.2"
      velocity="4" />
  </joint>
  <link
    name="lf_ankle_Link">
    <inertial>
      <origin
        xyz="0.037761 -0.014128 0.0005095"
        rpy="0 0 0" />
      <mass
        value="0.092" />
      <inertia
        ixx="9.9997E-06"
        ixy="8.2892E-06"
        ixz="-8.347E-08"
        iyy="1.1276E-05"
        iyz="-5.3773E-09"
        izz="1.9753E-05" />
    </inertial>
    <visual>
      <origin
        xyz="0 0 0"
        rpy="0 0 0" />
      <geometry>
        <mesh
          filename="../meshes/ankle_link.STL" />
      </geometry>
      <material
        name="">
        <color
          rgba="1 1 1 1" />
      </material>
    </visual>
    <collision>
      <origin
        xyz="0 0 0"
        rpy="0 0 0" />
      <geometry>
        <mesh
          filename="../meshes/ankle_link.STL" />
      </geometry>
    </collision>
  </link>
  <joint
    name="lf_ankle_joint"
    type="revolute">
    <origin
      xyz="0.07745 0 0.00015"
      rpy="0 0 0" />
    <parent
      link="lf_knee_Link" />
    <child
      link="lf_ankle_Link" />
    <axis
      xyz="0 0 -1" />
    <limit
      lower="-1.745"
      upper="1.745"
      effort="1.2"
      velocity="4" />
  </joint>
  <link
    name="lm_thigh_Link">
    <inertial>
      <origin
        xyz="0.019013 0.00032996 0.00011404"
        rpy="0 0 0" />
      <mass
        value="0.071" />
      <inertia
        ixx="2.5711E-06"
        ixy="1.9851E-08"
        ixz="-8.344E-08"
        iyy="2.9345E-06"
        iyz="-5.4072E-09"
        izz="4.3664E-06" />
    </inertial>
    <visual>
      <origin
        xyz="0 0 0"
        rpy="0 0 0" />
      <geometry>
        <mesh
          filename="../meshes/thigh_link.STL" />
      </geometry>
      <material
        name="">
        <color
          rgba="1 1 1 1" />
      </material>
    </visual>
    <collision>
      <origin
        xyz="0 0 0"
        rpy="0 0 0" />
      <geometry>
        <mesh
          filename="../meshes/thigh_link.STL" />
      </geometry>
    </collision>
  </link>
  <joint
    name="lm_thigh_joint"
    type="revolute">
    <origin
      xyz="-0.085 0 0.025996"
      rpy="0 0 -3.1416" />
    <parent
      link="base_link" />
    <child
      link="lm_thigh_Link" />
    <axis
      xyz="0 0 -1" />
    <limit
      lower="-0.698"
      upper="0.698"
      effort="1.2"
      velocity="4" />
  </joint>
  <link
    name="lm_knee_Link">
    <inertial>
      <origin
        xyz="0.024 0.00029496 0.00084693"
        rpy="0 0 0" />
      <mass
        value="0.079" />
      <inertia
        ixx="3.459E-06"
        ixy="1.9851E-08"
        ixz="-8.344E-08"
        iyy="6.155E-06"
        iyz="-5.4071E-09"
        izz="4.8098E-06" />
    </inertial>
    <visual>
      <origin
        xyz="0 0 0"
        rpy="0 0 0" />
      <geometry>
        <mesh
          filename="../meshes/knee_link.STL" />
      </geometry>
      <material
        name="">
        <color
          rgba="1 1 1 1" />
      </material>
    </visual>
    <collision>
      <origin
        xyz="0 0 0"
        rpy="0 0 0" />
      <geometry>
        <mesh
          filename="../meshes/knee_link.STL" />
      </geometry>
    </collision>
  </link>
  <joint
    name="lm_knee_joint"
    type="revolute">
    <origin
      xyz="0.05236 4.5E-05 -0.00075"
      rpy="1.5708 0 0" />
    <parent
      link="lm_thigh_Link" />
    <child
      link="lm_knee_Link" />
    <axis
      xyz="0 0 -1" />
    <limit
      lower="-2.094"
      upper="2.094"
      effort="1.2"
      velocity="4" />
  </joint>
  <link
    name="lm_ankle_Link">
    <inertial>
      <origin
        xyz="0.037761 -0.014128 0.00050942"
        rpy="0 0 0" />
      <mass
        value="0.092" />
      <inertia
        ixx="9.9998E-06"
        ixy="8.2893E-06"
        ixz="-8.3442E-08"
        iyy="1.1276E-05"
        iyz="-5.4062E-09"
        izz="1.9753E-05" />
    </inertial>
    <visual>
      <origin
        xyz="0 0 0"
        rpy="0 0 0" />
      <geometry>
        <mesh
          filename="../meshes/ankle_link.STL" />
      </geometry>
      <material
        name="">
        <color
          rgba="1 1 1 1" />
      </material>
    </visual>
    <collision>
      <origin
        xyz="0 0 0"
        rpy="0 0 0" />
      <geometry>
        <mesh
          filename="../meshes/ankle_link.STL" />
      </geometry>
    </collision>
  </link>
  <joint
    name="lm_ankle_joint"
    type="revolute">
    <origin
      xyz="0.07745 0 0.0002"
      rpy="0 0 0" />
    <parent
      link="lm_knee_Link" />
    <child
      link="lm_ankle_Link" />
    <axis
      xyz="0 0 -1" />
    <limit
      lower="-1.745"
      upper="1.745"
      effort="1.2"
      velocity="4" />
  </joint>
  <link
    name="lb_thigh_Link">
    <inertial>
      <origin
        xyz="0.019013 0.00032996 0.00086404"
        rpy="0 0 0" />
      <mass
        value="0.071" />
      <inertia
        ixx="2.5711E-06"
        ixy="1.9851E-08"
        ixz="-8.344E-08"
        iyy="2.9345E-06"
        iyz="-5.4072E-09"
        izz="4.3664E-06" />
    </inertial>
    <visual>
      <origin
        xyz="0 0 0"
        rpy="0 0 0" />
      <geometry>
        <mesh
          filename="../meshes/thigh_link.STL" />
      </geometry>
      <material
        name="">
        <color
          rgba="1 1 1 1" />
      </material>
    </visual>
    <collision>
      <origin
        xyz="0 0 0"
        rpy="0 0 0" />
      <geometry>
        <mesh
          filename="../meshes/thigh_link.STL" />
      </geometry>
    </collision>
  </link>
  <joint
    name="lb_thigh_joint"
    type="revolute">
    <origin
      xyz="-0.0425 -0.073612 0.025246"
      rpy="0 0 -2.0944" />
    <parent
      link="base_link" />
    <child
      link="lb_thigh_Link" />
    <axis
      xyz="0 0 -1" />
    <limit
      lower="-0.698"
      upper="1.571"
      effort="1.2"
      velocity="4" />
  </joint>
  <link
    name="lb_knee_Link">
    <inertial>
      <origin
        xyz="0.024 0.00029496 0.00084694"
        rpy="0 0 0" />
      <mass
        value="0.079" />
      <inertia
        ixx="3.459E-06"
        ixy="1.9852E-08"
        ixz="-8.3441E-08"
        iyy="6.155E-06"
        iyz="-5.4075E-09"
        izz="4.8098E-06" />
    </inertial>
    <visual>
      <origin
        xyz="0 0 0"
        rpy="0 0 0" />
      <geometry>
        <mesh
          filename="../meshes/knee_link.STL" />
      </geometry>
      <material
        name="">
        <color
          rgba="1 1 1 1" />
      </material>
    </visual>
    <collision>
      <origin
        xyz="0 0 0"
        rpy="0 0 0" />
      <geometry>
        <mesh
          filename="../meshes/knee_link.STL" />
      </geometry>
    </collision>
  </link>
  <joint
    name="lb_knee_joint"
    type="revolute">
    <origin
      xyz="0.05236 4.5E-05 0"
      rpy="1.5708 0 0" />
    <parent
      link="lb_thigh_Link" />
    <child
      link="lb_knee_Link" />
    <axis
      xyz="0 0 -1" />
    <limit
      lower="-2.094"
      upper="2.094"
      effort="1.2"
      velocity="4" />
  </joint>
  <link
    name="lb_ankle_Link">
    <inertial>
      <origin
        xyz="0.037761 -0.014128 0.00050936"
        rpy="0 0 0" />
      <mass
        value="0.092" />
      <inertia
        ixx="9.9996E-06"
        ixy="8.2892E-06"
        ixz="-8.3419E-08"
        iyy="1.1276E-05"
        iyz="-5.4295E-09"
        izz="1.9753E-05" />
    </inertial>
    <visual>
      <origin
        xyz="0 0 0"
        rpy="0 0 0" />
      <geometry>
        <mesh
          filename="../meshes/ankle_link.STL" />
      </geometry>
      <material
        name="">
        <color
          rgba="1 1 1 1" />
      </material>
    </visual>
    <collision>
      <origin
        xyz="0 0 0"
        rpy="0 0 0" />
      <geometry>
        <mesh
          filename="../meshes/ankle_link.STL" />
      </geometry>
    </collision>
  </link>
  <joint
    name="lb_ankle_joint"
    type="revolute">
    <origin
      xyz="0.07745 0 0.0002"
      rpy="0 0 0" />
    <parent
      link="lb_knee_Link" />
    <child
      link="lb_ankle_Link" />
    <axis
      xyz="0 0 -1" />
    <limit
      lower="-1.745"
      upper="1.745"
      effort="1.2"
      velocity="4" />
  </joint>
  <link
    name="rf_thigh_Link">
    <inertial>
      <origin
        xyz="0.019013 0.00032996 0.00086404"
        rpy="0 0 0" />
      <mass
        value="0.071" />
      <inertia
        ixx="2.5711E-06"
        ixy="1.9851E-08"
        ixz="-8.344E-08"
        iyy="2.9345E-06"
        iyz="-5.4072E-09"
        izz="4.3664E-06" />
    </inertial>
    <visual>
      <origin
        xyz="0 0 0"
        rpy="0 0 0" />
      <geometry>
        <mesh
          filename="../meshes/thigh_link.STL" />
      </geometry>
      <material
        name="">
        <color
          rgba="1 1 1 1" />
      </material>
    </visual>
    <collision>
      <origin
        xyz="0 0 0"
        rpy="0 0 0" />
      <geometry>
        <mesh
          filename="../meshes/thigh_link.STL" />
      </geometry>
    </collision>
  </link>
  <joint
    name="rf_thigh_joint"
    type="revolute">
    <origin
      xyz="0.0425 0.073612 0.025246"
      rpy="0 0 1.0472" />
    <parent
      link="base_link" />
    <child
      link="rf_thigh_Link" />
    <axis
      xyz="0 0 -1" />
    <limit
      lower="-0.698"
      upper="1.571"
      effort="1.2"
      velocity="4" />
  </joint>
  <link
    name="rf_knee_Link">
    <inertial>
      <origin
        xyz="0.024 0.00029496 0.00084694"
        rpy="0 0 0" />
      <mass
        value="0.079" />
      <inertia
        ixx="3.459E-06"
        ixy="1.9852E-08"
        ixz="-8.3441E-08"
        iyy="6.155E-06"
        iyz="-5.4075E-09"
        izz="4.8098E-06" />
    </inertial>
    <visual>
      <origin
        xyz="0 0 0"
        rpy="0 0 0" />
      <geometry>
        <mesh
          filename="../meshes/knee_link.STL" />
      </geometry>
      <material
        name="">
        <color
          rgba="1 1 1 1" />
      </material>
    </visual>
    <collision>
      <origin
        xyz="0 0 0"
        rpy="0 0 0" />
      <geometry>
        <mesh
          filename="../meshes/knee_link.STL" />
      </geometry>
    </collision>
  </link>
  <joint
    name="rf_knee_joint"
    type="revolute">
    <origin
      xyz="0.05236 4.5E-05 0"
      rpy="1.5708 0 0" />
    <parent
      link="rf_thigh_Link" />
    <child
      link="rf_knee_Link" />
    <axis
      xyz="0 0 1" />
    <limit
      lower="-2.094"
      upper="2.094"
      effort="1.2"
      velocity="4" />
  </joint>
  <link
    name="rf_ankle_Link">
    <inertial>
      <origin
        xyz="0.037761 -0.014128 0.00050936"
        rpy="0 0 0" />
      <mass
        value="0.092" />
      <inertia
        ixx="9.9996E-06"
        ixy="8.2892E-06"
        ixz="-8.3419E-08"
        iyy="1.1276E-05"
        iyz="-5.4295E-09"
        izz="1.9753E-05" />
    </inertial>
    <visual>
      <origin
        xyz="0 0 0"
        rpy="0 0 0" />
      <geometry>
        <mesh
          filename="../meshes/ankle_link.STL" />
      </geometry>
      <material
        name="">
        <color
          rgba="1 1 1 1" />
      </material>
    </visual>
    <collision>
      <origin
        xyz="0 0 0"
        rpy="0 0 0" />
      <geometry>
        <mesh
          filename="../meshes/ankle_link.STL" />
      </geometry>
    </collision>
  </link>
  <joint
    name="rf_ankle_joint"
    type="revolute">
    <origin
      xyz="0.07745 0 0.0002"
      rpy="0 0 0" />
    <parent
      link="rf_knee_Link" />
    <child
      link="rf_ankle_Link" />
    <axis
      xyz="0 0 1" />
    <limit
      lower="-1.745"
      upper="1.745"
      effort="1.2"
      velocity="4" />
  </joint>
  <link
    name="rm_thigh_Link">
    <inertial>
      <origin
        xyz="0.019013 0.00032996 0.00086404"
        rpy="0 0 0" />
      <mass
        value="0.071" />
      <inertia
        ixx="2.5711E-06"
        ixy="1.9851E-08"
        ixz="-8.344E-08"
        iyy="2.9345E-06"
        iyz="-5.4071E-09"
        izz="4.3664E-06" />
    </inertial>
    <visual>
      <origin
        xyz="0 0 0"
        rpy="0 0 0" />
      <geometry>
        <mesh
          filename="../meshes/thigh_link.STL" />
      </geometry>
      <material
        name="">
        <color
          rgba="1 1 1 1" />
      </material>
    </visual>
    <collision>
      <origin
        xyz="0 0 0"
        rpy="0 0 0" />
      <geometry>
        <mesh
          filename="../meshes/thigh_link.STL" />
      </geometry>
    </collision>
  </link>
  <joint
    name="rm_thigh_joint"
    type="revolute">
    <origin
      xyz="0.085 0 0.025246"
      rpy="0 0 0" />
    <parent
      link="base_link" />
    <child
      link="rm_thigh_Link" />
    <axis
      xyz="0 0 -1" />
    <limit
      lower="-0.698"
      upper="0.698"
      effort="1.2"
      velocity="4" />
  </joint>
  <link
    name="rm_knee_Link">
    <inertial>
      <origin
        xyz="0.024 0.00029496 0.00084693"
        rpy="0 0 0" />
      <mass
        value="0.079" />
      <inertia
        ixx="3.459E-06"
        ixy="1.9851E-08"
        ixz="-8.344E-08"
        iyy="6.155E-06"
        iyz="-5.4071E-09"
        izz="4.8098E-06" />
    </inertial>
    <visual>
      <origin
        xyz="0 0 0"
        rpy="0 0 0" />
      <geometry>
        <mesh
          filename="../meshes/knee_link.STL" />
      </geometry>
      <material
        name="">
        <color
          rgba="1 1 1 1" />
      </material>
    </visual>
    <collision>
      <origin
        xyz="0 0 0"
        rpy="0 0 0" />
      <geometry>
        <mesh
          filename="../meshes/knee_link.STL" />
      </geometry>
    </collision>
  </link>
  <joint
    name="rm_knee_joint"
    type="revolute">
    <origin
      xyz="0.05236 4.5E-05 0"
      rpy="1.5708 0 0" />
    <parent
      link="rm_thigh_Link" />
    <child
      link="rm_knee_Link" />
    <axis
      xyz="0 0 1" />
    <limit
      lower="-2.094"
      upper="2.094"
      effort="1.2"
      velocity="4" />
  </joint>
  <link
    name="rm_ankle_Link">
    <inertial>
      <origin
        xyz="0.037761 -0.014128 0.00050942"
        rpy="0 0 0" />
      <mass
        value="0.092" />
      <inertia
        ixx="9.9998E-06"
        ixy="8.2893E-06"
        ixz="-8.3442E-08"
        iyy="1.1276E-05"
        iyz="-5.4062E-09"
        izz="1.9753E-05" />
    </inertial>
    <visual>
      <origin
        xyz="0 0 0"
        rpy="0 0 0" />
      <geometry>
        <mesh
          filename="../meshes/ankle_link.STL" />
      </geometry>
      <material
        name="">
        <color
          rgba="1 1 1 1" />
      </material>
    </visual>
    <collision>
      <origin
        xyz="0 0 0"
        rpy="0 0 0" />
      <geometry>
        <mesh
          filename="../meshes/ankle_link.STL" />
      </geometry>
    </collision>
  </link>
  <joint
    name="rm_ankle_joint"
    type="revolute">
    <origin
      xyz="0.07745 0 0.0002"
      rpy="0 0 0" />
    <parent
      link="rm_knee_Link" />
    <child
      link="rm_ankle_Link" />
    <axis
      xyz="0 0 1" />
    <limit
      lower="-1.745"
      upper="1.745"
      effort="1.2"
      velocity="4" />
  </joint>
  <link
    name="rb_thigh_Link">
    <inertial>
      <origin
        xyz="0.019013 0.00032996 0.00086404"
        rpy="0 0 0" />
      <mass
        value="0.071" />
      <inertia
        ixx="2.5711E-06"
        ixy="1.9851E-08"
        ixz="-8.344E-08"
        iyy="2.9345E-06"
        iyz="-5.4072E-09"
        izz="4.3664E-06" />
    </inertial>
    <visual>
      <origin
        xyz="0 0 0"
        rpy="0 0 0" />
      <geometry>
        <mesh
          filename="../meshes/thigh_link.STL" />
      </geometry>
      <material
        name="">
        <color
          rgba="1 1 1 1" />
      </material>
    </visual>
    <collision>
      <origin
        xyz="0 0 0"
        rpy="0 0 0" />
      <geometry>
        <mesh
          filename="../meshes/thigh_link.STL" />
      </geometry>
    </collision>
  </link>
  <joint
    name="rb_thigh_joint"
    type="revolute">
    <origin
      xyz="0.0425 -0.073612 0.025246"
      rpy="0 0 -1.0472" />
    <parent
      link="base_link" />
    <child
      link="rb_thigh_Link" />
    <axis
      xyz="0 0 -1" />
    <limit
      lower="-1.571"
      upper="0.698"
      effort="1.2"
      velocity="4" />
  </joint>
  <link
    name="rb_knee_Link">
    <inertial>
      <origin
        xyz="0.024 0.00029496 0.00084694"
        rpy="0 0 0" />
      <mass
        value="0.079" />
      <inertia
        ixx="3.459E-06"
        ixy="1.9852E-08"
        ixz="-8.3439E-08"
        iyy="6.155E-06"
        iyz="-5.4073E-09"
        izz="4.8098E-06" />
    </inertial>
    <visual>
      <origin
        xyz="0 0 0"
        rpy="0 0 0" />
      <geometry>
        <mesh
          filename="../meshes/knee_link.STL" />
      </geometry>
      <material
        name="">
        <color
          rgba="1 1 1 1" />
      </material>
    </visual>
    <collision>
      <origin
        xyz="0 0 0"
        rpy="0 0 0" />
      <geometry>
        <mesh
          filename="../meshes/knee_link.STL" />
      </geometry>
    </collision>
  </link>
  <joint
    name="rb_knee_joint"
    type="revolute">
    <origin
      xyz="0.05236 4.5E-05 0"
      rpy="1.5708 0 0" />
    <parent
      link="rb_thigh_Link" />
    <child
      link="rb_knee_Link" />
    <axis
      xyz="0 0 1" />
    <limit
      lower="-2.094"
      upper="2.094"
      effort="1.2"
      velocity="4" />
  </joint>
  <link
    name="rb_ankle_Link">
    <inertial>
      <origin
        xyz="0.037761 -0.014128 0.00050943"
        rpy="0 0 0" />
      <mass
        value="0.092" />
      <inertia
        ixx="9.9998E-06"
        ixy="8.2893E-06"
        ixz="-8.3441E-08"
        iyy="1.1276E-05"
        iyz="-5.4067E-09"
        izz="1.9753E-05" />
    </inertial>
    <visual>
      <origin
        xyz="0 0 0"
        rpy="0 0 0" />
      <geometry>
        <mesh
          filename="../meshes/ankle_link.STL" />
      </geometry>
      <material
        name="">
        <color
          rgba="1 1 1 1" />
      </material>
    </visual>
    <collision>
      <origin
        xyz="0 0 0"
        rpy="0 0 0" />
      <geometry>
        <mesh
          filename="../meshes/ankle_link.STL" />
      </geometry>
    </collision>
  </link>
  <joint
    name="rb_ankle_joint"
    type="revolute">
    <origin
      xyz="0.07745 0 0.0002"
      rpy="0 0 0" />
    <parent
      link="rb_knee_Link" />
    <child
      link="rb_ankle_Link" />
    <axis
      xyz="0 0 1" />
    <limit
      lower="-1.745"
      upper="1.745"
      effort="1.2"
      velocity="4" />
  </joint>
</robot>